from django.core.exceptions import ValidationError
from rest_framework import serializers
from rest_framework.relations import SlugRelatedField

from posts.models import Comment, Follow, Group, Post, User


class PostSerializer(serializers.ModelSerializer):

    author = SlugRelatedField(slug_field='username', read_only=True)

    class Meta:
        model = Post
        fields = ('id', 'text', 'author', 'image', 'group', 'pub_date')
        read_only_fields = ('author',)


class CommentSerializer(serializers.ModelSerializer):

    author = serializers.SlugRelatedField(
        read_only=True, slug_field='username'
    )

    class Meta:
        model = Comment
        fields = ('id', 'author', 'post', 'text', 'created')
        read_only_fields = ('author', 'post')


class GroupSerializer(serializers.ModelSerializer):

    class Meta:
        fields = ('id', 'title', 'slug', 'description', 'posts')
        model = Group


class FollowSerializer(serializers.ModelSerializer):

    following = serializers.SlugRelatedField(
        read_only=False, slug_field='username', queryset=User.objects.all()
    )
    user = serializers.SlugRelatedField(
        slug_field='username',
        read_only=True,
        default=serializers.CurrentUserDefault(),
    )

    class Meta:
        fields = '__all__'
        model = Follow
        validators = [
            serializers.UniqueTogetherValidator(
                queryset=Follow.objects.all(), fields=('user', 'following')
            )
        ]

    def validate(self, attrs):
        if self.context['request'].user == attrs['following']:
            raise ValidationError('Подписка на самого себя запрещена')
        return attrs
